Recursion limit set to: 10 (logging fallback)
Traceback (most recent call last):
  File "D:\Analyzer\CreateMetaDb\main.py", line 28, in main
    info("SourceAnalyzer 시작")
  File "D:\Analyzer\CreateMetaDb\util\logger.py", line 148, in info
    app_logger.info(message)
  File "D:\Analyzer\CreateMetaDb\util\logger.py", line 68, in info
    self.logger.info(message)
  File "C:\Python313\Lib\logging\__init__.py", line 1522, in info
    self._log(INFO, msg, args, **kwargs)
  File "C:\Python313\Lib\logging\__init__.py", line 1665, in _log
    record = self.makeRecord(self.name, level, fn, lno, msg, args,
  File "C:\Python313\Lib\logging\__init__.py", line 1634, in makeRecord
    rv = _logRecordFactory(name, level, fn, lno, msg, args, exc_info, func,
  File "C:\Python313\Lib\logging\__init__.py", line 332, in __init__
    self.filename = os.path.basename(pathname)
  File "<frozen ntpath>", line 256, in basename
  File "<frozen ntpath>", line 228, in split
RecursionError: maximum recursion depth exceeded

During handling of the above exception, another exception occurred:

Traceback (most recent call last):
  File "D:\Analyzer\CreateMetaDb\main.py", line 173, in <module>
    main()
  File "D:\Analyzer\CreateMetaDb\main.py", line 145, in main
    handle_error(e, "프로그램 실행 중 오류 발생")
  File "D:\Analyzer\CreateMetaDb\util\logger.py", line 182, in handle_error
    app_logger.handle_error(error, custom_message, exit_code)
  File "D:\Analyzer\CreateMetaDb\util\logger.py", line 99, in handle_error
    tb = traceback.extract_tb(error.__traceback__)
  File "C:\Python313\Lib\traceback.py", line 78, in extract_tb
    return StackSummary._extract_from_extended_frame_gen(
  File "C:\Python313\Lib\traceback.py", line 500, in _extract_from_extended_frame_gen
    f.line
  File "C:\Python313\Lib\traceback.py", line 373, in line
    self._set_lines()
  File "C:\Python313\Lib\traceback.py", line 351, in _set_lines
    line = linecache.getline(self.filename, lineno).rstrip()
  File "C:\Python313\Lib\linecache.py", line 26, in getline
    lines = getlines(filename, module_globals)
  File "C:\Python313\Lib\linecache.py", line 42, in getlines
    return updatecache(filename, module_globals)
RecursionError: maximum recursion depth exceeded
