[INFO] Recursion limit set to: 10
[INFO] SourceAnalyzer 시작
[INFO] RecursionError in argparse: maximum recursion depth exceeded
[INFO] Using fallback argument parser
[INFO] Using fallback argument parsing
[INFO] RecursionError in regex validation, using fallback for: sampleSrc
[DEBUG] 인자 검증 성공
[INFO] 분석 대상 프로젝트: None
[INFO] 분석 옵션:
[INFO]   - 메타데이터베이스 초기화: False
[INFO]   - 상세 로그: False
[INFO]   - 출력 형식: html
[INFO]   - 드라이런 모드: False
[INFO]   - 강제 실행: False
[INFO] 1단계 실행: 파일 정보 저장 (프로젝트 전체 스캔)
[ERROR] RecursionError in traceback processing
Traceback (most recent call last):
  File "D:\Analyzer\CreateMetaDb\main.py", line 68, in main
    from file_loading import execute_file_scan
  File "<frozen importlib._bootstrap>", line 1360, in _find_and_load
  File "<frozen importlib._bootstrap>", line 1322, in _find_and_load_unlocked
  File "<frozen importlib._bootstrap>", line 1262, in _find_spec
  File "<frozen importlib._bootstrap_external>", line 1559, in find_spec
  File "<frozen importlib._bootstrap_external>", line 1533, in _get_spec
  File "<frozen importlib._bootstrap_external>", line 1665, in find_spec
  File "<frozen importlib._bootstrap_external>", line 166, in _path_isfile
  File "<frozen importlib._bootstrap_external>", line 158, in _path_is_mode_type
RecursionError: maximum recursion depth exceeded

During handling of the above exception, another exception occurred:

Traceback (most recent call last):
  File "D:\Analyzer\CreateMetaDb\main.py", line 169, in <module>
    main()
  File "D:\Analyzer\CreateMetaDb\main.py", line 141, in main
    handle_error(e, "프로그램 실행 중 오류 발생")
  File "D:\Analyzer\CreateMetaDb\util\logger.py", line 195, in handle_error
    app_logger.handle_error(error, custom_message, exit_code)
  File "D:\Analyzer\CreateMetaDb\util\logger.py", line 141, in handle_error
    self.logger.error(error_msg)
  File "C:\Python313\Lib\logging\__init__.py", line 1551, in error
    self._log(ERROR, msg, args, **kwargs)
  File "C:\Python313\Lib\logging\__init__.py", line 1665, in _log
    record = self.makeRecord(self.name, level, fn, lno, msg, args,
  File "C:\Python313\Lib\logging\__init__.py", line 1634, in makeRecord
    rv = _logRecordFactory(name, level, fn, lno, msg, args, exc_info, func,
  File "C:\Python313\Lib\logging\__init__.py", line 332, in __init__
    self.filename = os.path.basename(pathname)
  File "<frozen ntpath>", line 256, in basename
  File "<frozen ntpath>", line 228, in split
RecursionError: maximum recursion depth exceeded
