[INFO] Recursion limit set to: 10
[INFO] SourceAnalyzer 시작
Traceback (most recent call last):
  File "D:\Analyzer\CreateMetaDb\main.py", line 27, in main
    args = arg_utils.parse_args()
  File "D:\Analyzer\CreateMetaDb\util\arg_utils.py", line 112, in parse_args
    self.create_parser()
  File "D:\Analyzer\CreateMetaDb\util\arg_utils.py", line 33, in create_parser
    self.parser = argparse.ArgumentParser(
  File "C:\Python313\Lib\argparse.py", line 1781, in __init__
    superinit(description=description,
  File "C:\Python313\Lib\argparse.py", line 1399, in __init__
    self._negative_number_matcher = _re.compile(r'^-\d+$|^-\d*\.\d+$')
  File "C:\Python313\Lib\re\__init__.py", line 289, in compile
    return _compile(pattern, flags)
  File "C:\Python313\Lib\re\__init__.py", line 350, in _compile
    p = _compiler.compile(pattern, flags)
  File "C:\Python313\Lib\re\_compiler.py", line 748, in compile
    p = _parser.parse(p, flags)
  File "C:\Python313\Lib\re\_parser.py", line 973, in parse
    source = Tokenizer(str)
RecursionError: maximum recursion depth exceeded

During handling of the above exception, another exception occurred:

Traceback (most recent call last):
  File "D:\Analyzer\CreateMetaDb\main.py", line 169, in <module>
    main()
  File "D:\Analyzer\CreateMetaDb\main.py", line 141, in main
    handle_error(e, "프로그램 실행 중 오류 발생")
  File "D:\Analyzer\CreateMetaDb\util\logger.py", line 186, in handle_error
    app_logger.handle_error(error, custom_message, exit_code)
  File "D:\Analyzer\CreateMetaDb\util\logger.py", line 103, in handle_error
    tb = traceback.extract_tb(error.__traceback__)
  File "C:\Python313\Lib\traceback.py", line 78, in extract_tb
    return StackSummary._extract_from_extended_frame_gen(
  File "C:\Python313\Lib\traceback.py", line 500, in _extract_from_extended_frame_gen
    f.line
  File "C:\Python313\Lib\traceback.py", line 373, in line
    self._set_lines()
  File "C:\Python313\Lib\traceback.py", line 351, in _set_lines
    line = linecache.getline(self.filename, lineno).rstrip()
  File "C:\Python313\Lib\linecache.py", line 26, in getline
    lines = getlines(filename, module_globals)
  File "C:\Python313\Lib\linecache.py", line 42, in getlines
    return updatecache(filename, module_globals)
RecursionError: maximum recursion depth exceeded
