Traceback (most recent call last):
  File "D:\Analyzer\CreateMetaDb\main.py", line 17, in <module>
    info(f"Recursion limit set to: {sys.getrecursionlimit()}")
  File "D:\Analyzer\CreateMetaDb\util\logger.py", line 148, in info
    app_logger.info(message)
  File "D:\Analyzer\CreateMetaDb\util\logger.py", line 68, in info
    self.logger.info(message)
  File "C:\Python313\Lib\logging\__init__.py", line 1522, in info
    self._log(INFO, msg, args, **kwargs)
  File "C:\Python313\Lib\logging\__init__.py", line 1667, in _log
    self.handle(record)
  File "C:\Python313\Lib\logging\__init__.py", line 1686, in handle
    self.callHandlers(record)
  File "C:\Python313\Lib\logging\__init__.py", line 1744, in callHandlers
    hdlr.handle(record)
  File "C:\Python313\Lib\logging\__init__.py", line 1027, in handle
    self.emit(record)
  File "C:\Python313\Lib\logging\__init__.py", line 1151, in emit
    msg = self.format(record)
  File "C:\Python313\Lib\logging\__init__.py", line 999, in format
    return fmt.format(record)
RecursionError: maximum recursion depth exceeded
