2025-09-12 15:58:48,241 - SourceAnalyzer - INFO - logger.py:68 - SourceAnalyzer 시작
2025-09-12 15:58:48,249 - SourceAnalyzer - DEBUG - logger.py:64 - 명령행 인자 파싱 완료: {'project_name': 'sampleSrc', 'clear_metadb': True, 'verbose': False, 'output_format': 'html', 'config_file': None, 'log_level': 'INFO', 'dry_run': False, 'force': False}
2025-09-12 15:58:48,249 - SourceAnalyzer - DEBUG - logger.py:64 - 인자 검증 성공
2025-09-12 15:58:48,249 - SourceAnalyzer - INFO - logger.py:68 - 분석 대상 프로젝트: sampleSrc
2025-09-12 15:58:48,249 - SourceAnalyzer - INFO - logger.py:68 - 분석 옵션:
2025-09-12 15:58:48,249 - SourceAnalyzer - INFO - logger.py:68 -   - 메타데이터베이스 초기화: True
2025-09-12 15:58:48,249 - SourceAnalyzer - INFO - logger.py:68 -   - 상세 로그: False
2025-09-12 15:58:48,250 - SourceAnalyzer - INFO - logger.py:68 -   - 출력 형식: html
2025-09-12 15:58:48,250 - SourceAnalyzer - INFO - logger.py:68 -   - 드라이런 모드: False
2025-09-12 15:58:48,250 - SourceAnalyzer - INFO - logger.py:68 -   - 강제 실행: False
2025-09-12 15:58:48,250 - SourceAnalyzer - INFO - logger.py:68 - 프로젝트 분석 시작...
2025-09-12 15:58:48,251 - SourceAnalyzer - INFO - logger.py:68 - === 파일 스캔 시작: 파일 정보 저장 ===
2025-09-12 15:58:48,256 - SourceAnalyzer - ERROR - logger.py:128 - FATAL ERROR at D:\Analyzer\CreateMetaDb\file_loading.py:71 in initialize_database()
Code: os.remove(self.metadata_db_path)
Message: 메타데이터베이스 초기화 실패
Exception: PermissionError: [WinError 32] 다른 프로세스가 파일을 사용 중이기 때문에 프로세스가 액세스 할 수 없습니다: 'D:\\Analyzer\\CreateMetaDb\\projects\\sampleSrc\\metadata.db'
Stack Trace:
Traceback (most recent call last):
  File "D:\Analyzer\CreateMetaDb\file_loading.py", line 71, in initialize_database
    os.remove(self.metadata_db_path)
    ~~~~~~~~~^^^^^^^^^^^^^^^^^^^^^^^
PermissionError: [WinError 32] 다른 프로세스가 파일을 사용 중이기 때문에 프로세스가 액세스 할 수 없습니다: 'D:\\Analyzer\\CreateMetaDb\\projects\\sampleSrc\\metadata.db'

