2025-09-12 14:26:18,070 - SourceAnalyzer - DEBUG - logger.py:64 - 파일 읽기 성공: config/parser/sql_keyword.yaml
2025-09-12 14:26:18,092 - SourceAnalyzer - DEBUG - logger.py:64 - YAML 설정 파일 로드 성공: config/parser/sql_keyword.yaml
2025-09-12 14:26:18,093 - SourceAnalyzer - DEBUG - logger.py:64 - 파일 읽기 성공: config/parser/mybatis_keyword.yaml
2025-09-12 14:26:18,104 - SourceAnalyzer - DEBUG - logger.py:64 - YAML 설정 파일 로드 성공: config/parser/mybatis_keyword.yaml
2025-09-12 14:26:18,104 - SourceAnalyzer - DEBUG - logger.py:64 - 파일 읽기 성공: config/parser/sql_keyword.yaml
2025-09-12 14:26:18,122 - SourceAnalyzer - DEBUG - logger.py:64 - YAML 설정 파일 로드 성공: config/parser/sql_keyword.yaml
2025-09-12 14:26:18,122 - SourceAnalyzer - INFO - logger.py:68 - === 4-2단계 XML 쿼리 관계 분석 시작 ===
2025-09-12 14:26:18,126 - SourceAnalyzer - ERROR - logger.py:128 - FATAL ERROR at <frozen os>:228 in makedirs()
Message: 데이터베이스 연결 실패: metadata.db
Exception: FileNotFoundError: [WinError 3] 지정된 경로를 찾을 수 없습니다: ''
Stack Trace:
Traceback (most recent call last):
  File "D:\Analyzer\CreateMetaDb\util\database_utils.py", line 39, in connect
    os.makedirs(os.path.dirname(self.db_path), exist_ok=True)
    ~~~~~~~~~~~^^^^^^^^^^^^^^^^^^^^^^^^^^^^^^^^^^^^^^^^^^^^^^
  File "<frozen os>", line 228, in makedirs
FileNotFoundError: [WinError 3] 지정된 경로를 찾을 수 없습니다: ''

