2025-09-12 14:52:18,389 - SourceAnalyzer - INFO - logger.py:68 - SourceAnalyzer 시작
2025-09-12 14:52:18,395 - SourceAnalyzer - DEBUG - logger.py:64 - 명령행 인자 파싱 완료: {'project_name': 'sampleSrc', 'clear_metadb': False, 'verbose': False, 'output_format': 'html', 'config_file': None, 'log_level': 'INFO', 'dry_run': False, 'force': False}
2025-09-12 14:52:18,395 - SourceAnalyzer - DEBUG - logger.py:64 - 인자 검증 성공
2025-09-12 14:52:18,395 - SourceAnalyzer - INFO - logger.py:68 - 분석 대상 프로젝트: sampleSrc
2025-09-12 14:52:18,395 - SourceAnalyzer - INFO - logger.py:68 - 분석 옵션:
2025-09-12 14:52:18,395 - SourceAnalyzer - INFO - logger.py:68 -   - 메타데이터베이스 초기화: False
2025-09-12 14:52:18,396 - SourceAnalyzer - INFO - logger.py:68 -   - 상세 로그: False
2025-09-12 14:52:18,396 - SourceAnalyzer - INFO - logger.py:68 -   - 출력 형식: html
2025-09-12 14:52:18,396 - SourceAnalyzer - INFO - logger.py:68 -   - 드라이런 모드: False
2025-09-12 14:52:18,396 - SourceAnalyzer - INFO - logger.py:68 -   - 강제 실행: False
2025-09-12 14:52:18,396 - SourceAnalyzer - INFO - logger.py:68 - 프로젝트 분석 시작...
2025-09-12 14:52:18,397 - SourceAnalyzer - INFO - logger.py:68 - === 파일 스캔 시작: 파일 정보 저장 ===
2025-09-12 14:52:19,884 - SourceAnalyzer - ERROR - logger.py:128 - FATAL ERROR at D:\Analyzer\CreateMetaDb\util\database_utils.py:51 in connect()
Code: self.connection.execute("PRAGMA journal_mode = WAL")
Message: 데이터베이스 연결 실패: D:\Analyzer\CreateMetaDb\projects\sampleSrc\metadata.db
Exception: OperationalError: disk I/O error
Stack Trace:
Traceback (most recent call last):
  File "D:\Analyzer\CreateMetaDb\util\database_utils.py", line 51, in connect
    self.connection.execute("PRAGMA journal_mode = WAL")
    ~~~~~~~~~~~~~~~~~~~~~~~^^^^^^^^^^^^^^^^^^^^^^^^^^^^^
sqlite3.OperationalError: disk I/O error

2025-09-12 14:52:19,885 - SourceAnalyzer - DEBUG - logger.py:64 - 데이터베이스 연결 해제: D:\Analyzer\CreateMetaDb\projects\sampleSrc\metadata.db
