2025-09-12 21:00:51,058 - SourceAnalyzer - INFO - logger.py:68 - SourceAnalyzer 시작
2025-09-12 21:00:51,064 - SourceAnalyzer - DEBUG - logger.py:64 - 명령행 인자 파싱 완료: {'project_name': 'sampleSrc', 'clear_metadb': True, 'verbose': False, 'output_format': 'html', 'config_file': None, 'log_level': 'INFO', 'dry_run': False, 'force': False}
2025-09-12 21:00:51,064 - SourceAnalyzer - DEBUG - logger.py:64 - 인자 검증 성공
2025-09-12 21:00:51,064 - SourceAnalyzer - INFO - logger.py:68 - 분석 대상 프로젝트: sampleSrc
2025-09-12 21:00:51,064 - SourceAnalyzer - INFO - logger.py:68 - 분석 옵션:
2025-09-12 21:00:51,064 - SourceAnalyzer - INFO - logger.py:68 -   - 메타데이터베이스 초기화: True
2025-09-12 21:00:51,065 - SourceAnalyzer - INFO - logger.py:68 -   - 상세 로그: False
2025-09-12 21:00:51,065 - SourceAnalyzer - INFO - logger.py:68 -   - 출력 형식: html
2025-09-12 21:00:51,065 - SourceAnalyzer - INFO - logger.py:68 -   - 드라이런 모드: False
2025-09-12 21:00:51,065 - SourceAnalyzer - INFO - logger.py:68 -   - 강제 실행: False
2025-09-12 21:00:51,065 - SourceAnalyzer - INFO - logger.py:68 - 1단계 실행: 파일 정보 저장 (프로젝트 전체 스캔)
2025-09-12 21:00:51,066 - SourceAnalyzer - INFO - logger.py:68 - === 파일 스캔 시작: 파일 정보 저장 ===
2025-09-12 21:00:51,072 - SourceAnalyzer - ERROR - logger.py:128 - FATAL ERROR at D:\Analyzer\CreateMetaDb\file_loading.py:71 in initialize_database()
Code: os.remove(self.metadata_db_path)
Message: 메타데이터베이스 초기화 실패
Exception: PermissionError: [WinError 5] 액세스가 거부되었습니다: 'D:\\Analyzer\\CreateMetaDb\\projects\\sampleSrc\\metadata.db'
Stack Trace:
Traceback (most recent call last):
  File "D:\Analyzer\CreateMetaDb\file_loading.py", line 71, in initialize_database
    os.remove(self.metadata_db_path)
    ~~~~~~~~~^^^^^^^^^^^^^^^^^^^^^^^
PermissionError: [WinError 5] 액세스가 거부되었습니다: 'D:\\Analyzer\\CreateMetaDb\\projects\\sampleSrc\\metadata.db'

